Workbook
Name _ftnref1: 'SOF - AI-Enabled SOC'!#REF!
Name _ftnref12: 'SOF - AI-Enabled SOC'!#REF!
Name _ftnref13: 'SOF - AI-Enabled SOC'!#REF!
Name _ftnref16: 'SOF - AI-Enabled SOC'!#REF!
Name _ftnref4: 'SOF - AI-Enabled SOC'!#REF!
Name _ftnref7: 'SOF - AI-Enabled SOC'!#REF!
Name _ftnref8: 'SOF - AI-Enabled SOC'!#REF!
Name _ftnref9: 'SOF - AI-Enabled SOC'!#REF!
Name CML: 'SOF - AI-Enabled SOC'!$A$56:$A$64
Name LevelSet: 'SOF - AI-Enabled SOC'!#REF!
Name LevelSet: #REF!
Name SelectIII: #REF!

Sheet Rollup
A1: SOC instance to model: <Customer name>-<SOC Name> | H1: Calc'd | I1: Set | K1: Created/edited by: | L1: Todd Ray | M1: 45992
A2: SOF - AI-Enabled SOC - CMM Categories | C2: People | D2: Process | E2: Technology / Platform | F2: Data / Telemetry & TI | G2: Governance / Compliance | H2: Ops Model & Services | I2: Metrics / Outcomes | J2: Top Tier Gaps (Subcategory) (these are calculated based on the set values in the "SOF - AI-Enabled SOC" sheet and the Target values on this sheet. ) | M2: Threshold
A3: SOC CMM Average Scoring - Current State | C3: =IFERROR( AVERAGEIFS( 'SOF - AI-Enabled SOC'!$F$3:$F$35, 'SOF - AI-Enabled SOC'!$B$3:$B$35, C2, 'SOF - AI-Enabled SOC'!$F$3:$F$35, ">0" ), 0 ) -> 112.5 | D3: =IFERROR( AVERAGEIFS( 'SOF - AI-Enabled SOC'!$F$3:$F$35, 'SOF - AI-Enabled SOC'!$B$3:$B$35, D2, 'SOF - AI-Enabled SOC'!$F$3:$F$35, ">0" ), 0 ) -> 100 | E3: =IFERROR( AVERAGEIFS( 'SOF - AI-Enabled SOC'!$F$3:$F$35, 'SOF - AI-Enabled SOC'!$B$3:$B$35, E2, 'SOF - AI-Enabled SOC'!$F$3:$F$35, ">0" ), 0 ) -> 162.5 | F3: =IFERROR( AVERAGEIFS( 'SOF - AI-Enabled SOC'!$F$3:$F$35, 'SOF - AI-Enabled SOC'!$B$3:$B$35, F2, 'SOF - AI-Enabled SOC'!$F$3:$F$35, ">0" ), 0 ) -> 150 | G3: =IFERROR( AVERAGEIFS( 'SOF - AI-Enabled SOC'!$F$3:$F$35, 'SOF - AI-Enabled SOC'!$B$3:$B$35, G2, 'SOF - AI-Enabled SOC'!$F$3:$F$35, ">0" ), 0 ) -> 112.5 | H3: =IFERROR( AVERAGEIFS( 'SOF - AI-Enabled SOC'!$F$3:$F$35, 'SOF - AI-Enabled SOC'!$B$3:$B$35, H2, 'SOF - AI-Enabled SOC'!$F$3:$F$35, ">0" ), 0 ) -> 130 | I3: =IFERROR( AVERAGEIFS( 'SOF - AI-Enabled SOC'!$F$3:$F$35, 'SOF - AI-Enabled SOC'!$B$3:$B$35, I2, 'SOF - AI-Enabled SOC'!$F$3:$F$35, ">0" ), 0 ) -> 130 | J3: Set the gap threshold to limit the result set to gaps higher than a threshold (to use for (e.g.) prioritization; to see all parameter, set to a high positive number (e.g., +100)) | M3: 100
B4: Target | C4: 250 | D4: 250 | E4: 250 | F4: 275 | G4: 300 | H4: 250 | I4: 300 | J4: N=33 | K4: Top Tier Gaps (Subcategory) | L4: Category | M4: Gap (Score - CatTarg)
B5: Overall gap (for Category) | C5: =C3-C4 -> -137.5 | D5: =D3-D4 -> -150 | E5: =E3-E4 -> -87.5 | F5: =F3-F4 -> -125 | G5: =G3-G4 -> -187.5 | H5: =H3-H4 -> -120 | I5: =I3-I4 -> -170 | J5: 1 | K5: {=_xlfn.LET( _xlpm.sub, 'SOF - AI-Enabled SOC'!$C$3:$C$35, _xlpm.cat, 'SOF - AI-Enabled SOC'!$B$3:$B$35, _xlpm.gap, 'SOF - AI-Enabled SOC'!$H$3:$H$35, _xlpm.data, CHOOSE({1,2,3}, _xlpm.sub, _xlpm.cat, _xlpm.gap), _xlpm.valid, _xlfn._xlws.FILTER( _xlpm.data, ISNUMBER(_xlpm.gap) * (_xlpm.gap <= Rollup!$M$3) ), _xlfn._xlws.SORT(_xlpm.valid, 3, 1) )} -> Generative AI governance & oversight | L5: Governance / Compliance | M5: -250
J6: =J5+1 -> 2 | K6: AI agent governance & lifecycle | L6: Governance / Compliance | M6: -250
J7: =J6+1 -> 3 | K7: Autonomous operations metrics | L7: Metrics / Outcomes | M7: -250
J8: =J7+1 -> 4 | K8: Analyst augmentation with GenAI | L8: People | M8: -200
J9: =J8+1 -> 5 | K9: AI & automation skills development | L9: People | M9: -200
J10: =J9+1 -> 6 | K10: AI-assisted investigation & response | L10: Process | M10: -200
J11: =J10+1 -> 7 | K11: Agentic workflows & continuous learning | L11: Process | M11: -200
J12: =J11+1 -> 8 | K12: Automated Incident Response & Containment | L12: Process | M12: -200
J13: =J12+1 -> 9 | K13: DevSecOps & Supply Chain Security | L13: Process | M13: -200
J14: =J13+1 -> 10 | K14: AI-assisted analysis & threat hunting | L14: Technology / Platform | M14: -200
J15: =J14+1 -> 11 | K15: AI integration program & norms | L15: Ops Model & Services | M15: -200
J16: =J15+1 -> 12 | K16: Autonomous SOC operations planning | L16: Ops Model & Services | M16: -200
J17: =J16+1 -> 13 | K17: Business outcome metrics | L17: Metrics / Outcomes | M17: -200
... J19: =J18+1 -> 15 | K19: Continuous learning from telemetry | L19: Data / Telemetry & TI | M19: -175
J20: 16 | K20: Operational governance & auditability | L20: Governance / Compliance | M20: -150
J21: =J20+1 -> 17 | K21: SOC service catalog | L21: Ops Model & Services | M21: -150
J22: =J21+1 -> 18 | K22: Coverage & quality metrics | L22: Metrics / Outcomes | M22: -150
J23: =J22+1 -> 19 | K23: Analyst performance metrics | L23: Metrics / Outcomes | M23: -150
J24: =J23+1 -> 20 | K24: Normalization & correlation | L24: Data / Telemetry & TI | M24: -125
J25: =J24+1 -> 21 | K25: Multi-skilled SOC analysts | L25: People | M25: -100
J26: =J25+1 -> 22 | K26: Proactive exposure & posture management | L26: Process | M26: -100
J27: =J26+1 -> 23 | K27: Unified SOC platform (XDR + SIEM) | L27: Technology / Platform | M27: -100
J28: =J27+1 -> 24 | K28: Cloud Security Posture Management | L28: Technology / Platform | M28: -100
J29: =J28+1 -> 25 | K29: Cyber governance & compliance | L29: Governance / Compliance | M29: -100
J30: =J29+1 -> 26 | K30: Efficiency metrics (MTTD/MTTR) | L30: Metrics / Outcomes | M30: -100
J31: =J30+1 -> 27 | K31: End-to-end telemetry coverage | L31: Data / Telemetry & TI | M31: -75
J32: =J31+1 -> 28 | K32: Threat Intelligence & Adversary Tracking | L32: Data / Telemetry & TI | M32: -75
... J37: =J36+1 -> 33 | K37: Identity Security & Phishing Defense | L37: Technology / Platform | M37: 50

Sheet SOF - AI-Enabled SOC
B1: AI-Enabled SOC - CMM - Post Ignite '25 | E1: Contoso SOC Example | F1: (replace example value w/customer value) | I1: <Hidden columns provide calculations for gap ranking.
A2: Original # sequence | B2: Primary Category | C2: Sub-category | D2: Description | E2: Degree of adoption (example customer) | F2: Current Level (Customer) | G2: Primary Category Target (from "Rollup Sheet" | H2: Gap (Level - Target) | I2: 1 — Not started or starting (0,50) | J2: 2 — Planning / Developing (100, 150) | K2: 3 — Rolling out / Standardizing (200, 250) | L2: 4 — Operating / Optimizing (300, 350) | M2: Comments | N2: Applicable Stds/Regs Mapping | O2: Explanation of Applicability
A3: 1 | B3: People | C3: Multi-skilled SOC analysts | D3: Tiered SOC roles are blended to reduce handoffs; analysts are cross-trained to handle incidents end-to-end in a pod model. | E3: Moderately adopted; concept is established but requires significant organizational change (many SOCs still operate in silos). | F3: 150 | G3: =IFERROR( _xlfn.XLOOKUP( B3, Rollup!$C$2:$I$2, Rollup!$C$4:$I$4 ), "" ) -> 250 | H3: =F3-G3 -> -100 | I3: Roles unclear; SOC tiers work in silos. | J3: Skills matrix defined; cross-training plan in place. | K3: Majority of analysts cross-trained; fewer handoffs across incident lifecycle. | L3: Full pod model implemented for investigations; workload balancing largely automated. | M3: – | N3: NIST CSF (PR.AT), ISO/IEC 27001 (Annex A 6.3), CIS (Control 14) | O3: NIST CSF’s Protect – Awareness and Training (PR.AT) domain and ISO/IEC 27001 require that personnel be adequately trained and competent in security duties. Having multi-skilled SOC analysts aligns with these by ensuring roles and responsibilities are understood and staff are cross-trained. CIS Control 14 (Security Awareness and Skills Training) likewise emphasizes developing staff skills. This capability ensures compliance with the expectation that organizations maintain a knowledgeable workforce to handle incidents effectively.
A4: 2 | B4: People | C4: Embedded security engineering | D4: Dedicated “behind the glass” security engineering team exists to manage SOC tooling, content, and automation (platform integration, analytics tuning, etc.). | E4: Increasingly adopted in mature SOCs; having a dedicated engineering team for SOC tooling and automation is recognized as best practice. | F4: 200 | G4: =IFERROR( _xlfn.XLOOKUP( B4, Rollup!$C$2:$I$2, Rollup!$C$4:$I$4 ), "" ) -> 250 | H4: =F4-G4 -> -50 | I4: No dedicated security engineering function (reactive or ad-hoc only). | J4: Part-time or ad-hoc engineering support assigned to the SOC. | K4: Dedicated SecEng team in place managing integrations, detection content, etc. | L4: Proactive SecEng function fully integrated; backlog handled with metrics-driven improvements. | M4: – | N4: ISO/IEC 27001 (Cl. 5.3 & 7.2), NIST CSF (DE.DP & PR.IP domains) | O4: ISO 27001 requires clear assignment of security roles (Cl. 5.3) and ensuring staff have appropriate skills (Cl. 7.2). Maintaining an engineering function to continuously tune detections and automate responses supports NIST CSF’s Detection Processes (DE.DP-5) – “processes are continuously improved” – and Protective Technology (PR.PT) outcomes. In practice, an embedded SecEng team addresses these standards by formalizing the upkeep of monitoring tools and ensuring changes (e.g. new detection rules, system configurations) follow a controlled process (ISO 27001 A.12.1.2 Change Management).
A5: 3 | B5: People | C5: Analyst augmentation with GenAI | D5: SOC analysts leverage generative AI (e.g. Security Copilot) to accelerate data gathering, triage, and investigation steps, appropriate to their roles (juniors speed up basics, seniors dive deeper faster). Post Ignite ’25 insights: | E5: Very new capability (emerging post-Ignite 2025); few organizations have deployed generative AI assistants widely in SOC operations yet. | F5: 50 | G5: =IFERROR( _xlfn.XLOOKUP( B5, Rollup!$C$2:$I$2, Rollup!$C$4:$I$4 ), "" ) -> 250 | H5: =F5-G5 -> -200 | I5: No access to generative AI tools for SOC analysts. | J5: Initial pilots of Copilot/GenAI assistants with a limited subset of analysts. | K5: GenAI assistants broadly available; all analysts trained on AI-driven workflows. | L5: GenAI embedded in daily operations for triage/investigation; measurable gains in analyst efficiency and insights. | M5: Includes role‑tailored AI experiences: e.g. threat intel analysts use specialized prompts; executives receive narrative summaries. | N5: NIST AI RMF, ISO/IEC 23894, EU AI Act (transparency & oversight) | O5: The use of generative AI in operations introduces AI-specific risks. NIST AI RMF provides a framework to identify and mitigate these (e.g. ensuring accuracy, managing bias). ISO/IEC 23894:2023 offers similar lifecycle-based AI risk guidance. If the AI qualifies as high-risk, the EU AI Act imposes transparency and human oversight requirements (e.g. human review of AI suggestions and a “stop” mechanism for automated actions[1]). This capability therefore must be governed by AI risk management practices – ensuring outputs are verified and that AI tools are used in line with ethical and regulatory guidelines for trustworthy AI.
A6: 4 | B6: People | C6: AI & automation skills development | D6: The organization develops new skills for managing AI-driven and autonomous operations – e.g. prompt engineering, agent orchestration, AI ethics and reliability oversight. | E6: Nascent area; most SOCs are only beginning to train staff in AI-specific skills (e.g. prompt engineering, AI oversight) if at all. | F6: 50 | G6: =IFERROR( _xlfn.XLOOKUP( B6, Rollup!$C$2:$I$2, Rollup!$C$4:$I$4 ), "" ) -> 250 | H6: =F6-G6 -> -200 | I6: Necessary AI/automation skills are absent in the team. | J6: Training plans established to build AI and autonomous operations skills. | K6: Core team trained in AI governance, agent orchestration, and related skills. | L6: AI and autonomy skills adopted SOC-wide; staff proficient in overseeing and co-working with AI agents. | M6: – | N6: NIST CSF (PR.AT), NIST AI RMF (Govern function), ISO/IEC 27001 (Cl. 7.2) | O6: Beyond general security training, NIST AI RMF’s Govern function highlights cultivating a culture of risk management for AI, which includes training personnel on AI oversight roles. NIST CSF PR.AT (Awareness Training) and ISO 27001’s competence and awareness clauses require organizations to equip staff with skills needed for emerging technologies. Developing AI and automation skills ensures the SOC can safely operate and supervise AI tools, meeting these expectations. It’s about extending standard training requirements to cover AI-specific competencies (e.g. prompt engineering, understanding AI limitations) so that human operators remain in control of AI-augmented processes.
A7: 5 | B7: Process | C7: Standardized & streamlined processes | D7: Key SOC processes (monitoring, investigation, response, etc.) are documented as SOPs with clear entry/exit criteria, roles (RACI), and escalation paths, and continuously refined. | E7: Widely practiced; documenting and refining SOC procedures (with RACI, playbooks, etc.) is a long-standing goal largely in place at mature organizations. | F7: 250 | G7: =IFERROR( _xlfn.XLOOKUP( B7, Rollup!$C$2:$I$2, Rollup!$C$4:$I$4 ), "" ) -> 250 | H7: =F7-G7 -> 0 | I7: Processes ad hoc and inconsistent; roles & handoffs unclear. | J7: Core SOC procedures drafted and roles/responsibilities defined (SOPs in development). | K7: Standard operating procedures approved and in use; workflows are clearly defined and enforced (predictable handoffs, RACI in place). | L7: Processes routinely reviewed and optimized (metrics-driven improvements, minimal friction in workflows). | M7: – | N7: ISO/IEC 27035 (Incident Mgmt Process), ISO/IEC 27001 (Cl. 8 & A.16), NIST CSF (RS.RP & RS.IM) | O7: ISO/IEC 27035 prescribes a structured incident management process[2] [3], requiring clear phases (preparation, detection, analysis, response, lessons learned). ISO 27001 similarly requires documented operational procedures (Cl. 8.1) and incident response plans (Annex A.16). NIST CSF’s Respond domain (RS) calls for maintained incident response plans (RS.RP-1) and improvements from lessons learned (RS.IM-1). This capability aligns with those standards by having well-defined, auditable SOPs for all SOC activities, ensuring consistency and compliance in how incidents and daily monitoring are handled.
A8: 6 | B8: Process | C8: Proactive exposure & posture management | D8: The SOC actively monitors and reduces the organization’s attack surface (vulnerability management, cloud configuration, etc.), not just reacting to incidents. | E8: Partially implemented; vulnerability and patch management are common, but fully integrating attack surface reduction into SOC workflows remains challenging. | F8: 150 | G8: =IFERROR( _xlfn.XLOOKUP( B8, Rollup!$C$2:$I$2, Rollup!$C$4:$I$4 ), "" ) -> 250 | H8: =F8-G8 -> -100 | I8: Exposure management is purely reactive (patching after incidents). | J8: Vulnerability scanning tools selected and basic remediation runbooks drafted. | K8: Regular scans and attack surface reviews in place; remediation SLAs defined and tracked. | L8: Continuous exposure management with risk-based prioritization of fixes; configuration drift and known weaknesses are promptly addressed. | M8: Defender now integrates with DevOps pipelines – enabling “shift-left” security: code vulnerabilities are caught early and linked to runtime threats for faster mitigation. | N8: NIST CSF (ID.RA & PR.MA), CIS (Controls 1, 7), ISO/IEC 27001 (Annex A 8.8) | O8: Proactively managing vulnerabilities and configurations is mandated by multiple frameworks. NIST CSF’s Identify – Risk Assessment (ID.RA) and Protect – Maintenance (PR.MA-1) include vulnerability identification and patch management. CIS Controls (e.g. Control 7: Continuous Vulnerability Management) specify processes for regular scanning and remediation. ISO/IEC 27001:2022 Annex A 8.8 explicitly requires a technical vulnerability management process, i.e. obtaining info on vulnerabilities, evaluating exposure, and taking appropriate measures[4]. Meeting these standards means the SOC doesn’t just react to incidents but actively reduces risk by hardening systems, patching, and minimizing misconfigurations.
A9: 7 | B9: Process | C9: AI-assisted investigation & response | D9: Analysts use natural-language interfaces and AI suggestions to handle incidents (e.g. “explain this alert” or timeline generation); prompt guides (prompt books) and verification steps ensure consistency. | E9: Early stage; relies on new AI tooling (e.g. Security Copilot suggestions) that is just entering use, so broad adoption is minimal so far. | F9: 50 | G9: =IFERROR( _xlfn.XLOOKUP( B9, Rollup!$C$2:$I$2, Rollup!$C$4:$I$4 ), "" ) -> 250 | H9: =F9-G9 -> -200 | I9: No AI assistance in investigations or response (all steps manual). | J9: Initial use of AI in investigations (some prompt patterns/assistants piloted). | K9: Defined prompt playbooks and AI-driven suggestions integrated into standard operating procedures for triage/response. | L9: Predominantly AI-driven workflows: analysts interact via Copilot/AI for most steps, with humans validating high-impact actions as needed. | M9: – | N9: NIST CSF (DE.DP & RS.AN), NIST AI RMF, ISO/IEC 42001 | O9: Augmenting incident handling with AI must still fulfill core incident response standards. NIST CSF’s Detection and Response processes (DE.DP, RS.AN) require timely analysis and action, which AI can accelerate. However, the introduction of AI is governed by NIST AI RMF and ISO/IEC 42001 (AI Management System) – these ensure that AI tools in decision-making roles are managed, tested, and have human oversight. In practice, this means even if an AI recommends a containment action, frameworks would require that its use is well-controlled (e.g. results logged and reviewed, per ISO 42001 and AI RMF “Measure/Manage” functions). This capability should be implemented such that AI expedites work, but final accountability and verification remain with human operators, satisfying both traditional IR standards and new AI governance.
A10: 8 | B10: Process | C10: Agentic workflows & continuous learning | D10: Autonomous “security agent” workflows execute complex tasks (threat hunts, incident response actions) based on goals, and improve over time by learning from outcomes (feedback loops, retained knowledge). | E10: Experimental; fully autonomous “security agent” workflows are still largely theoretical or in limited pilots at best. | F10: 50 | G10: =IFERROR( _xlfn.XLOOKUP( B10, Rollup!$C$2:$I$2, Rollup!$C$4:$I$4 ), "" ) -> 250 | H10: =F10-G10 -> -200 | I10: All investigation and response tasks executed manually (no autonomous workflows). | J10: Candidate use cases for autonomous agents identified (design of agent workflows in progress). | K10: Autonomous agent-driven workflows operating for specific tasks (goal-driven sequences with supervised self-evaluation). | L10: Agents continuously learn from each engagement, improving efficacy (patterns reused, decisions refined) with minimal human intervention. | M10: – | N10: NIST AI RMF, ISO/IEC 42001, EU AI Act (if high-risk) | O10: Deploying autonomous “agentic” workflows touches emerging AI governance regimes. NIST AI RMF emphasizes continuous monitoring and adjustment of AI behaviors (the “Manage” function) – applicable to agents that learn from outcomes. ISO/IEC 42001:2023 (AI Management System) would require formal management of such AI-driven processes as part of the organizational system of controls (including risk assessments before deployment and ongoing performance evaluation). If the autonomous agents impact critical decisions or safety, the EU AI Act could classify them as high-risk, triggering requirements for human oversight, fail-safes, and rigorous risk management[5] [6]. Therefore, this capability must be pursued under strict governance: clearly defined agent objectives, monitoring of agent decisions, and the ability for humans to intervene (a principle enshrined in AI regulations).
A11: 32 | B11: Process | C11: Automated Incident Response & Containment | D11: - XDR platforms can automatically contain threats: predictive shielding anticipates attacker moves and hardens targets; automatic attack disruption extends containment to third-party systems (e.g. AWS, Okta). - Transforms IR from manual/reactive playbooks to proactive defense, with autonomous containment actions executed at machine speed. | E11: Very new capability (just introduced); outside of early adopters, most SOCs still rely on manual or basic scripted incident response. These advanced autonomous containment features are only beginning to see pilot use in cutting-edge SOCs. | F11: 50 | G11: =IFERROR( _xlfn.XLOOKUP( B11, Rollup!$C$2:$I$2, Rollup!$C$4:$I$4 ), "" ) -> 250 | H11: =F11-G11 -> -200 | I11: All incident containment actions are manual (no automation). | J11: Basic automated scripts for containment exist for a few scenarios (isolating a host, disabling an account) but usage is limited and requires human initiation. | K11: Autonomous containment is enabled for common threats (e.g. auto-isolation of infected endpoints), including some third-party integrations; analysts supervise and fine-tune these automated actions | L11: Predominantly AI-driven, preemptive containment in place – the SOC’s XDR auto-hardens assets and disrupts attacks across on-prem and cloud with minimal human intervention (analysts oversee policies and intervene only when needed). | N11: NIST CSF (RS.MI), ISO/IEC 27035, CIS (Control 17) | O11: Incident response standards demand timely containment and mitigation of incidents. NIST CSF’s Respond Mitigation (RS.MI) emphasizes rapid action to contain threats, which this capability delivers via automation. ISO/IEC 27035 (incident management guidelines) and CIS Control 17 (Incident Response) likewise require defined response procedures – implementing automated containment still needs to follow approved playbooks and logging to meet these controls. By using autonomous tools under human oversight, the SOC accelerates containment while remaining compliant (ensuring that each automated action is auditable and aligns with the organization’s incident response policies).
A12: 33 | B12: Process | C12: DevSecOps & Supply Chain Security | D12: - The SOC extends into development: security tools (e.g. Defender for Cloud) integrate with code repositories and CI/CD pipelines to catch vulnerabilities early and tie them to runtime incidents for fast mitigation. - Close collaboration with DevOps: code security findings (vulnerabilities, dependency risks) are handled as part of incident response, effectively “shift-left” – addressing threats in development to protect the software supply chain. | E12: Nascent area; few organizations have fully merged DevOps pipelines with SOC workflows. Some forward-leaning teams have begun linking code scan results to SOC alerts, but generally DevSecOps integration into incident response is in very early stages across the industry. | F12: 50 | G12: =IFERROR( _xlfn.XLOOKUP( B12, Rollup!$C$2:$I$2, Rollup!$C$4:$I$4 ), "" ) -> 250 | H12: =F12-G12 -> -200 | I12: Development vulnerabilities are handled separately by developers (SOC not involved in code security). | J12: Initial coordination between SOC and development teams established (e.g. sharing major vulnerability findings), but no formal integration; handling of code issues remains ad-hoc. | K12: Security scanning in CI/CD pipelines is connected to SOC monitoring – critical code flaws trigger alerts to the SOC, and analysts work with DevOps on remediation; supply chain risks are getting incorporated into incident workflows. | L12: Fully integrated DevSecOps workflow: code and pipeline security is a standard part of SOC operations. The SOC receives real-time alerts from development (vuln scans, repository changes) and uses AI-assisted tools to remediate issues quickly. “Shift-left” is achieved – the SOC and DevOps function as one team on security, | N12: NIST CSF (ID.SC), CIS (Control 16), ISO/IEC 27001 (secure development & supplier controls) | O12: Frameworks increasingly require managing software and supply chain risks as part of cybersecurity. NIST CSF’s Supply Chain Risk Management (ID.SC) domain calls for understanding and mitigating risks from third-party software and development practices. CIS Control 16 (Application Software Security) mandates processes like code review, vulnerability scanning, and remediation in the development lifecycle. ISO/IEC 27001 also includes controls for secure development and supplier security (ensuring software is built and maintained securely and that vendor risks are managed). By integrating DevSecOps into the SOC, this capability meets those obligations – it brings code vulnerabilities and software supply chain issues into the same governed process as operational security incidents. This ensures compliance with standards that insist on end-to-end security (from code creation to runtime), and helps the organization proactively address weaknesses before they can be exploited in production.
A13: 9 | B13: Technology / Platform | C13: Unified SOC platform (XDR + SIEM) | D13: A unified security operations platform integrates XDR and SIEM capabilities, providing a single console for detection, investigation, and response across on-prem and cloud environments. | E13: In progress at many organizations; tools are maturing, but most SOCs still juggle multiple consoles, and true single-pane-of-glass operations are not yet universal. | F13: 150 | G13: =IFERROR( _xlfn.XLOOKUP( B13, Rollup!$C$2:$I$2, Rollup!$C$4:$I$4 ), "" ) -> 250 | H13: =F13-G13 -> -100 | I13: Disparate security tools (XDR, SIEM, etc.) with no unified interface. | J13: Core XDR and SIEM platforms deployed; initial integration in progress. | K13: Mostly unified SOC interface achieved (cross-product incident views and shared workspaces across tools). | L13: Fully integrated “single pane of glass” SOC platform (analysts navigate a seamless interface and can take cross-tool actions in one place). | M13: – | N13: NIST CSF (DE.AE-3, DE.CM), CIS (Control 8), ISO/IEC 27001 (Annex A 8.14) | O13: A unified platform supports compliance by ensuring security events are centrally collected and correlated. NIST CSF Detect – Anomalies and Events includes subcategory DE.AE-3: “Event data are aggregated and correlated from multiple sources”[7], which directly aligns with having an integrated SIEM/XDR. CIS Control 8 (Audit Log Management) mandates centralized log storage and analysis. ISO/IEC 27001:2022 has Annex A 8.14 (Security information event monitoring), which expects organizations to monitor and analyze events across systems. Implementing a unified SOC platform operationalizes these requirements by providing comprehensive visibility and faster detection through correlation, which frameworks view as essential to effective monitoring.
A14: 10 | B14: Technology / Platform | C14: Cloud Security Posture Management | D14: - Visibility and security configuration management across multi-cloud assets (Azure, AWS, GCP, etc.) are unified in the SOC (XDR Dashboard), including serverless and cloud workloads. - Up-to-date asset inventory and risk score across all environments. - Continuous monitoring of cloud app configurations (including serverless) as part of routine posture audits. | E14: Mixed adoption; basic cloud posture tools exist for each platform, but unified multi-cloud visibility (including serverless environments) is just developing in practice. | F14: 150 | G14: =IFERROR( _xlfn.XLOOKUP( B14, Rollup!$C$2:$I$2, Rollup!$C$4:$I$4 ), "" ) -> 250 | H14: =F14-G14 -> -100 | I14: No centralized visibility into cloud asset posture (cloud security handled in silos). | J14: Cloud asset inventory being planned; basic posture assessment processes defined. | K14: Asset inventory and risk scoring in place for primary clouds; misconfigurations and weaknesses identified routinely. | L14: Unified multi-cloud and even serverless posture management operational, with continuous monitoring and risk scoring of all cloud resources. | M14: Multi-cloud posture now unified: the XDR/SIEM platform provides one dashboard for Azure/AWS/GCP, expanding the SOC’s view to include serverless functions and more. | N14: NIST CSF (ID.AM, PR.IP), CIS (Control 1 & Cloud Benchmarks), ISO/IEC 27001 (Annex A 5.9 & 8.8) | O14: Ensuring security across Azure, AWS, GCP, etc., ties into asset management and config hardening mandates. NIST CSF Identify – Asset Management (ID.AM) requires identification of assets (including cloud services) and Protect – Information Protection Processes (PR.IP-1) calls for a baseline configuration. CIS Control 1 (Inventory of Assets) now extends to cloud resources, and CIS provides cloud-specific benchmarks to maintain secure configurations. ISO/IEC 27001:2022 Annex A 5.9 (Inventory of assets) and 8.8 (technical vulnerability management) together imply organizations must inventory cloud assets and address their vulnerabilities/misconfigurations. By employing a Cloud Security Posture Management tool, the SOC can continuously meet these standards: keeping an updated inventory, monitoring for misconfigurations or unpatched cloud components, and thereby reducing cloud-related risk exposure.
A15: 11 | B15: Technology / Platform | C15: Identity Security & Phishing Defense | D15: - Strong identity-focused security practices in place: enterprise-wide phishing-resistant MFA, user behavior analytics, and training to counter advanced phishing (including deepfakes). - Even advanced attacks can be mitigated by MFA (blocking 99%+ of account takeover attempts). | E15: Well-established; most enterprises have broadly implemented MFA and phishing training, driven by high threat awareness and compliance requirements (advanced techniques like deepfake detection are still emerging). | F15: 300 | G15: =IFERROR( _xlfn.XLOOKUP( B15, Rollup!$C$2:$I$2, Rollup!$C$4:$I$4 ), "" ) -> 250 | H15: =F15-G15 -> 50 | I15: Multi-factor authentication (MFA) not implemented (or only basic); phishing training ad-hoc. | J15: Organization planning broad MFA rollout and formal phishing awareness training. | K15: MFA enforced for most users; phishing defenses include user training and some anomaly detection (e.g. suspicious login alerts). | L15: Phishing-resistant MFA deployed enterprise-wide; AI-driven detection of impersonation and other identity attacks actively protecting users. | M15: Deepfake impersonations and novel phishing techniques surged. Defenders are deploying AI-based anomaly detection for identity threats and intensifying user education. | N15: NIST CSF (PR.AC & PR.AT), CIS (Control 6 & 14), ISO/IEC 27001 (Annex A 5.11 & 7.2) | O15: Strong identity controls and phishing protection are well-covered by standards. NIST CSF Protect – Identity Management & Access Control (PR.AC) requires that access to assets is limited to authorized users/devices (which implies MFA and robust authentication), and Protect – Awareness Training (PR.AT) covers phishing awareness for personnel. CIS Control 6 (Access Control Management) specifically prescribes MFA and account management, while CIS Control 14 deals with security awareness (including phishing exercises). ISO/IEC 27001:2022 includes Annex A 5.11 (User access management) and Annex A 6.3 (awareness training) enforcing similar practices. Adopting enterprise-wide phishing-resistant MFA and regular phishing training addresses these requirements by reducing unauthorized access risk and improving user readiness against social engineering.
A16: 12 | B16: Technology / Platform | C16: AI-assisted analysis & threat hunting | D16: - The SOC employs generative AI agents to sift logs, identify patterns, and assist in threat hunting and detection engineering (e.g. suggesting queries or automating hypotheses generation). - Natural language “Threat-Hunting Agents” and Copilot-driven workflows. - Defined procedures for validating AI outputs - Agents integrated into daily triage and hunting. | E16: New capability; very few SOCs have AI-driven hunting or automated log analysis beyond initial UEBA features or limited Copilot trials. | F16: 50 | G16: =IFERROR( _xlfn.XLOOKUP( B16, Rollup!$C$2:$I$2, Rollup!$C$4:$I$4 ), "" ) -> 250 | H16: =F16-G16 -> -200 | I16: No AI assistance in log analysis or threat hunting (fully manual). | J16: Pilot projects using AI for basic alert triage or log analysis in development. | K16: Copilot/AI agents being rolled out to aid threat hunting and analysis (e.g. automated log summarization, anomaly spotting). | L16: AI agents are fully integrated into detection and hunting workflows; even non-expert analysts launch complex hunts via natural language queries. | M16: Generative AI has moved from pilot to pervasive – Security Copilot now includes dozens of built-in agents for log analysis, alert triage, identity risk, etc., democratizing advanced hunting. | N16: NIST CSF (DE.AE-5), NIST AI RMF, ISO/IEC 23894 | O16: Enhanced analytics with AI still map to detection requirements. NIST CSF Detect – DE.AE-5 notes that detection processes are continuously improved and updated to address evolving threats (using advanced analytics fits this) and might be seen in CSF 2.0 updates (e.g., integrating threat intel and context[8]). Introducing AI to do this triggers NIST AI RMF and ISO 23894 guidance to ensure the AI models used for hunting are reliable (e.g. tuning to avoid false positives/negatives, validating that AI-proposed anomalies truly indicate threats). In short, the capability aligns with standard detection objectives (broad and adaptive monitoring) while requiring AI risk management so that the “augmented hunting” is trustworthy and doesn’t introduce blind spots or errors.
A17: 13 | B17: Data / Telemetry & TI | C17: End-to-end telemetry coverage | D17: Comprehensive telemetry collection across endpoints, identities, email, network, and cloud (and OT/ICS where applicable) to ensure no blind spots in detection. | E17: High focus; most SOCs ingest telemetry from all key sources (endpoints, network, cloud), though achieving near-total coverage across an enterprise is still a work in progress. | F17: 200 | G17: =IFERROR( _xlfn.XLOOKUP( B17, Rollup!$C$2:$I$2, Rollup!$C$4:$I$4 ), "" ) -> 275 | H17: =F17-G17 -> -75 | I17: Only minimal security logs/sources are collected. | J17: Coverage plan established to onboard all critical telemetry sources. | K17: ~80–90% of required data sources sending telemetry; remaining gaps identified and tracked. | L17: >90% of environments covered by telemetry; any gaps are automatically flagged for remediation. | M17: – | N17: NIST CSF (DE.CM-1, DE.CM-7), CIS (Control 8), ISO/IEC 27001 (Annex A 8.14) | O17: Comprehensive logging underpins many security controls. NIST CSF Detect – Security Continuous Monitoring has DE.CM-1: networks are monitored, DE.CM-7: monitoring for unauthorized entities in systems. Essentially, all critical environments should be covered by telemetry. CIS Control 8 (System Audit Log Management) requires collecting logs from network, endpoint, and cloud systems and ensuring they are reviewed. ISO/IEC 27001 Annex A 8.14 similarly expects event monitoring across systems. Achieving end-to-end coverage demonstrates compliance with these, as it means the organization is not “flying blind” in any area. It also supports other controls (e.g., incident response) by ensuring data is available for analysis.
A18: 14 | B18: Data / Telemetry & TI | C18: Normalization & correlation | D18: Security data is normalized to common schemas and correlated, enabling entity-centric and incident-centric views with context (asset info, threat intel) attached to alerts. | E18: Moderate maturity; basic event correlation via SIEM is common, but fully normalized, context-rich correlation and entity linking are not yet universally achieved. | F18: 150 | G18: =IFERROR( _xlfn.XLOOKUP( B18, Rollup!$C$2:$I$2, Rollup!$C$4:$I$4 ), "" ) -> 275 | H18: =F18-G18 -> -125 | I18: Logs are siloed and unnormalized (raw data only, difficult to cross-correlate). | J18: Basic normalization in place for some data sources. | K18: Unified schema adopted; events from multiple sources are correlated into incidents and entity (asset/user) profiles. | L18: Richly correlated incidents with entity graphs and context (threat intel enrichment, etc.) provide high-fidelity alerts. | M18: – | N18: NIST CSF (DE.AE-3, DE.AE-4), ISO/IEC 27001 (Annex A 8.14), CIS (Control 8) | O18: NIST CSF highlights the importance of analyzing events in context: DE.AE-3 (event data are aggregated/correlated) and DE.AE-4 (anomalous events are analyzed and prioritized). This implies use of normalized data to effectively correlate across sources[9]. ISO 27001’s logging and monitoring control (A.8.14) calls for analysis of logs, which presumes some level of normalization to be efficient. CIS Control 8 also emphasizes ensuring logs are managed in a way that facilitates identifying meaningful patterns. By implementing common schemas (like ASIM or ECS for logs) and correlation engines, the SOC meets these expectations—detecting complex attack chains that single-source analysis would miss, as envisioned by the standards.
A19: 15 | B19: Data / Telemetry & TI | C19: Threat Intelligence & Adversary Tracking | D19: - Threat intelligence feeds (IOCs, actor TTPs) are integrated, and the SOC tracks adversary campaigns. Intel is applied to detect and proactively hunt threats, including those emerging on the dark web. - Behavior-based detection and dark web monitoring to counter increasingly AI-augmented, credential-focused attacks). | E19: Common practice; many SOCs integrate threat intelligence feeds and watch for known TTPs, although proactive adversary tracking depth varies by organization. | F19: 200 | G19: =IFERROR( _xlfn.XLOOKUP( B19, Rollup!$C$2:$I$2, Rollup!$C$4:$I$4 ), "" ) -> 275 | H19: =F19-G19 -> -75 | I19: No threat intelligence integrated into SOC monitoring. | J19: One threat feed/source piloted in SOC tools. | K19: Multiple threat intel sources actively integrated (indicators matched, actor profiles available). | L19: Threat intel fully operationalized – feeds from many sources (incl. dark web) inform detections and hunting; adversary campaigns are tracked and used to adapt defenses. | M19: Adversary tactics have escalated (infostealers, dark web credential markets). SOC intel now must cover AI-driven social engineering and the booming “access-as-a-service” cybercrime economy. | N19: NIST CSF (ID.RA-2, DE.AE-5), ISO/IEC 27001 (Annex A 5.7), CIS (Control 17) | O19: Consuming and using threat intelligence is increasingly part of best practices. NIST CSF’s Identify – Risk Assessment (ID.RA-2) states “Threat and vulnerability information is received from information sharing forums and sources” – encouraging use of cyber threat intel. CSF v2.0 adds DE.AE-07 for integrating threat intelligence into analysis[10]. ISO/IEC 27001:2022 introduced control 5.7 Threat intelligence, which says organizations should collect and analyze information on threats[11]. CIS Control 17 (Incident Response) also advises leveraging intel to preempt incidents. Mapping to these, this capability ensures the SOC ingests IOC feeds, attacker TTP reports, etc., and proactively hunts or adjusts defenses based on that intel – all actions that those standards aim for to stay ahead of emerging threats.
A20: 16 | B20: Data / Telemetry & TI | C20: Knowledge capture | D20: The SOC captures investigation context, summaries, and rationales in case records. This knowledge is indexed for future retrieval, aiding in learning from past incidents. | E20: Underdeveloped; while post-incident reports exist, systematic capture and reuse of investigation learnings (case knowledge base) is often ad hoc or inconsistent. | F20: 100 | G20: =IFERROR( _xlfn.XLOOKUP( B20, Rollup!$C$2:$I$2, Rollup!$C$4:$I$4 ), "" ) -> 275 | H20: =F20-G20 -> -175 | I20: Lessons and investigation details are not systematically captured. | J20: Templates defined for capturing key findings and decisions in incident reports. | K20: Investigation summaries and analyst reasoning are automatically captured for each case. | L20: Past case knowledge is leveraged in new investigations (similar cases retrieved with context; “institutional memory” informs current ops). | M20: – | N20: ISO/IEC 27035 (Post-Incident Lessons), NIST CSF (RS.IM & RC.IM), ISO/IEC 27001 (Cl. 10) | O20: Both NIST CSF and ISO incident management emphasize learning from incidents. NIST CSF’s Respond/Recover – Improvements (RS.IM-1, RC.IM-1) mandate incorporating lessons learned into updated response plans and strategies. ISO/IEC 27035 (and ISO 27001’s continual improvement clause 10) require that after an incident, organizations analyze what happened and improve future processes (this inherently means capturing and retrieving knowledge on past incidents). By systematically documenting investigation details, root causes, and remediation steps in a knowledge base, the SOC aligns with these standards: it creates an institutional memory that feeds back into training, playbooks, and threat models, closing the loop for continuous improvement and compliance.
A21: 17 | B21: Data / Telemetry & TI | C21: Continuous learning from telemetry | D21: Machine learning models continuously analyze telemetry to detect anomalies across users, endpoints, and environments; models retrain and improve as new data comes in. | E21: Emerging; some SOC tools offer ML-based anomaly detection, but continuously tuning and improving these models with local telemetry is not yet widespread. | F21: 100 | G21: =IFERROR( _xlfn.XLOOKUP( B21, Rollup!$C$2:$I$2, Rollup!$C$4:$I$4 ), "" ) -> 275 | H21: =F21-G21 -> -175 | I21: No machine-learning-based anomaly detection on SOC data. | J21: Plan in development to deploy anomaly detection pipelines (ML models) on security data. | K21: Initial ML jobs running, detecting anomalies across entities and environments (outliers flagged for review). | L21: Continuous ML analytics tuned and improving over time (drift monitored; models adapt to new patterns to reduce false negatives). | M21: – | N21: NIST CSF (DE.AE-5, DE.DP-5), ISO/IEC 27001 (Cl. 10), NIST AI RMF (Measure/Manage) | O21: While not explicitly required by older standards, this capability is an advanced extension of the “continuous improvement” ethos. NIST CSF DE.AE-5 notes that detection strategies are updated to reflect evolving threats – employing machine learning on telemetry fulfills this by adapting baselines and spotting new anomalies. DE.DP-5 (Detection processes continuously improved) also resonates. ISO 27001’s continual improvement (Cl. 10) encourages leveraging new techniques to enhance controls. If AI/ML is used, NIST AI RMF would apply to ensure the models are evaluated for effectiveness and fairness (Measure function) and managed over time (Manage function). In summary, using ML for anomaly detection can strengthen compliance by improving detection accuracy, but it must be accompanied by governance of the models to ensure they remain effective and don’t introduce risk (e.g., blind spots or concept drift).
A22: 18 | B22: Governance / Compliance | C22: Cyber governance & compliance | D22: - Cybersecurity is managed as a business risk: regular board/executive oversight, tracked via key metrics (e.g. MFA coverage, patch times) and aligned with major frameworks/regulations. - Compliance with frameworks (e.g. NIST CSF 2.0) and regulations (e.g. EU AI Act). -Senior leadership briefed on SOC metrics and alignment with new and updated standards. - AI risk management integrated into GRC charters, procedures, and processes. - Regulatory scrutiny extended to AI use in security operations. | E22: Improving; due to regulations and board pressure, more organizations are instituting executive cyber risk reviews and aligning with frameworks (maturity still varies). | F22: 200 | G22: =IFERROR( _xlfn.XLOOKUP( B22, Rollup!$C$2:$I$2, Rollup!$C$4:$I$4 ), "" ) -> 300 | H22: =F22-G22 -> -100 | I22: Cyber risk is not discussed at board level; minimal executive reporting. | J22: Planning to report cybersecurity posture to executives and align with emerging standards. | K22: Standardized cyber metrics (MFA coverage, IR time, etc.) reported to leadership; partial adoption of new frameworks. | L22: Full integration of cyber risk into governance (board-level dashboards, compliance with NIST CSF 2.0, EU AI Act, etc.; AI risk management included in charters). | M22: There’s heightened emphasis on treating cyber risk as a board-level issue. New frameworks (NIST CSF 2.0, EU AI Act, etc.) are raising compliance requirements, demanding more rigorous reporting and oversight. | N22: NIST CSF (ID.GV), ISO/IEC 27001 (Cl. 5 & 6), EU AI Act (AI risk governance) | O22: Strong governance is a cornerstone of most frameworks. NIST CSF Identify – Governance (ID.GV) demands that organizational roles, policies, and legal/regulatory requirements are understood and addressed at the governance level. ISO/IEC 27001 Clause 5 (leadership) requires top management involvement and Clause 6.1.1 mandates considering regulatory and contractual obligations in the ISMS – meaning the SOC’s strategy and metrics should be reviewed by leadership. Recent regulations like the EU AI Act (for organizations deploying AI) further require an AI governance structure and management of AI risks at the highest levels. Thus, this capability ensures that cybersecurity (and AI security) are treated as business risks: a board-reviewed program with metrics (e.g., MFA coverage, incident trends[12]) and compliance checks against frameworks (NIST CSF, ISO 27001, etc.), rather than solely an IT issue.
A23: 19 | B23: Governance / Compliance | C23: Operational governance & auditability | D23: Day-to-day SOC operations have governance controls: changes to detection content or playbooks follow change control, and evidence from investigations is captured for audits and compliance. | E23: Moderate; change control for SOC content and evidence retention exists in many places, but fully auditable, formalized processes are still being developed in others. | F23: 150 | G23: =IFERROR( _xlfn.XLOOKUP( B23, Rollup!$C$2:$I$2, Rollup!$C$4:$I$4 ), "" ) -> 300 | H23: =F23-G23 -> -150 | I23: No formal change control for SOC content; evidence collection ad hoc. | J23: Change management process defined (CAB for analytics/automation changes) and evidence templates introduced. | K23: Change control enforced for SOC updates (approval gates for rules, runbooks) and investigation evidence captured by default. | L23: Fully auditable operations: change decisions metrics-driven (with rollback plans); investigation evidence and activity logs automatically collected and auditable. | M23: – | N23: ISO/IEC 27001 (Annex A 8.1.4 & A.16.1.7), ISO/IEC 27035, NIST CSF (PR.IP-3, RS.AN-3) | O23: The ability to audit SOC actions and govern changes ties into multiple controls. ISO 27001 Annex A 8.1.4 mandates change management procedures (applicable to SOC content changes like new detection rules or playbooks), and A.16.1.7 requires securing evidence of incidents (for potential legal or forensic use). ISO 27035 also highlights maintaining incident logs and evidence. NIST CSF Protect – Configuration Change Control (PR.IP-3) calls for management of changes to organizational systems, and Respond – Analysis (RS.AN-3) states that forensics/evidence collection are performed following an incident. Implementing this capability – e.g., requiring approvals for rule changes and preserving incident data – meets those criteria. It ensures the SOC can demonstrate what was done and why, which is critical for passing audits (internal or external) and for any post-incident investigations or compliance reviews.
A24: 20 | B24: Governance / Compliance | C24: Generative AI governance & oversight | D24: Policies and guardrails are in place for SOC use of generative AI (e.g. Security Copilot): prompt content is reviewed, outputs are logged and validated, and human oversight is mandated for high-impact decisions. | E24: Nascent; few organizations have established formal policies or oversight for using generative AI (like Copilot) in security, given these tools only recently entered production. | F24: 50 | G24: =IFERROR( _xlfn.XLOOKUP( B24, Rollup!$C$2:$I$2, Rollup!$C$4:$I$4 ), "" ) -> 300 | H24: =F24-G24 -> -250 | I24: No specific policies or logging for AI assistance usage in the SOC. | J24: Draft AI usage policy in place (e.g. guidelines for Copilot prompts); partial logging of AI outputs. | K24: GenAI usage is governed with defined approval checkpoints and full logging of all prompts and AI-generated content. | L24: Regular audits of AI assistance outputs and decisions; prompt policies and validation checks are continuously refined based on oversight findings. | M24: – | N24: NIST AI RMF, ISO/IEC 42001, EU AI Act (transparency), ISO/IEC 27001 (Cl. 8 & A.12)* | O24: When integrating tools like Security Copilot, organizations must extend their governance to cover AI usage. NIST AI RMF provides a blueprint for this: e.g., establishing an AI use policy, risk assessments for AI outputs, and human oversight requirements (AI RMF “Govern” and “Manage” functions). ISO/IEC 42001 similarly would require defining processes to control AI systems and their outputs as part of an AI Management System. The EU AI Act (for high-risk or generative AI systems) enforces transparency (users must know they are interacting with AI, and have documentation of AI decision logic) and human control[13]. While ISO/IEC 27001 doesn’t explicitly mention AI, its risk management processes (Cl. 6) and operational controls (like A.12 for change management) should incorporate these AI policies. In practice, this means the SOC should have specific guidelines for using AI assistance (e.g. what tasks it can/cannot do, how analysts validate AI-provided information, logging of AI queries/results for audit) to ensure compliance and maintain trustworthiness of AI-augmented decisions.
... A35: 31 | B35: Metrics / Outcomes | C35: Autonomous operations metrics | D35: New metrics assess the impact of automation/AI: percentage of incidents handled autonomously vs. with human input, agent error rates or rollbacks, and the shift in human workloads (toward proactive vs. reactive work). | E35: Nonexistent-to-minimal; since truly autonomous SOC functions are rare today, few organizations have defined metrics for agent-driven operations or measure automation rates in a granular way. | F35: 50 | G35: =IFERROR( _xlfn.XLOOKUP( B35, Rollup!$C$2:$I$2, Rollup!$C$4:$I$4 ), "" ) -> 300 | H35: =F35-G35 -> -250 | I35: No tracking of the effect of AI/autonomy on SOC operations. | J35: Baseline established for automation levels and agent error rates (if any). | K35: Trends show increasing automation with acceptable error rates; some analyst capacity freed for higher-value tasks (tracked qualitatively). | L35: Quantitative targets for autonomy reached (e.g. X% of alerts auto-handled) with minimal safety incidents; analysts’ focus has shifted to strategic tasks and overall cost per incident is reduced. | M35: – | N35: NIST AI RMF (Measure), ISO/IEC 42001, ISO/IEC 27001 (Cl. 9 & 10) | O35: As organizations implement more automation, it’s important (and in line with emerging standards) to measure its performance and risks. NIST AI RMF – Measure function explicitly calls for identifying metrics to track AI system performance and impact. For a partially autonomous SOC, relevant metrics might be “percentage of alerts resolved by AI without human intervention” or “number of AI actions reverted by humans.” ISO/IEC 42001 would require monitoring of the AI Management System’s objectives – if one objective is to automate X% of tasks, progress and any incidents (e.g., AI mistakes) should be quantitatively tracked. ISO 27001’s general monitoring (Cl.9) and improvement (Cl.10) clauses also support this: the SOC should evaluate how automation affects its overall risk posture and adjust accordingly. Including these metrics ensures that autonomy is delivering value without compromising security; for example, if an automated action causes an incident, that would be measured and fed back into policy (perhaps triggering more human oversight) as part of continual improvement. (Note: Capabilities marked with an asterisk () involve standards beyond the original reference list, included for completeness.)*
B37: References
B38: [1]https://www.aoshearman.com/en/insights/ao-shearman-on-tech/zooming-in-on-ai-10-eu-ai-act-what-are-the-obligations-for-high-risk-ai-systems
B39: [2]https://www.neumetric.com/journal/iso-27035-incident-response-plan-2962/
B40: [3]https://www.neumetric.com/journal/iso-27035-incident-response-plan-2962/
B41: [4]https://hightable.io/iso-27001-annex-a-8-8-management-of-technical-vulnerabilities/
B42: [5]https://www.aoshearman.com/en/insights/ao-shearman-on-tech/zooming-in-on-ai-10-eu-ai-act-what-are-the-obligations-for-high-risk-ai-systems
B43: [6]https://www.aoshearman.com/en/insights/ao-shearman-on-tech/zooming-in-on-ai-10-eu-ai-act-what-are-the-obligations-for-high-risk-ai-systems
B44: [7]https://csf.tools/reference/nist-cybersecurity-framework/v1-1/de/de-ae/de-ae-3/
B45: [8]https://csf.tools/reference/nist-cybersecurity-framework/v1-1/de/de-ae/de-ae-3/
B46: [9]https://csf.tools/reference/nist-cybersecurity-framework/v1-1/de/de-ae/de-ae-3/
B47: [10]https://csf.tools/reference/nist-cybersecurity-framework/v1-1/de/de-ae/de-ae-3/
B48: [11]https://morganhillcg.com/blog/item/iso-iec-27002-2022-5-7-threat-intelligence-program-template
... B53: [16]https://microsoft-my.sharepoint.com/personal/toddray_microsoft_com/_layouts/15/Doc.aspx?sourcedoc=%7B5E8C34D9-4722-4D84-9D50-0C13E82B1D9A%7D&file=SOF%20CMM%20Post-Ignite%20Additions.docx&action=default&mobileredirect=true
A55: Lookup
A56: 0
...
